Traceback (most recent call last):
  File "/opt/conda/lib/python3.10/site-packages/jupyter_cache/executors/utils.py", line 58, in single_nb_execution
    executenb(
  File "/opt/conda/lib/python3.10/site-packages/nbclient/client.py", line 1305, in execute
    return NotebookClient(nb=nb, resources=resources, km=km, **kwargs).execute()
  File "/opt/conda/lib/python3.10/site-packages/jupyter_core/utils/__init__.py", line 166, in wrapped
    return loop.run_until_complete(inner)
  File "/opt/conda/lib/python3.10/asyncio/base_events.py", line 649, in run_until_complete
    return future.result()
  File "/opt/conda/lib/python3.10/site-packages/nbclient/client.py", line 705, in async_execute
    await self.async_execute_cell(
  File "/opt/conda/lib/python3.10/site-packages/nbclient/client.py", line 1058, in async_execute_cell
    await self._check_raise_for_error(cell, cell_index, exec_reply)
  File "/opt/conda/lib/python3.10/site-packages/nbclient/client.py", line 914, in _check_raise_for_error
    raise CellExecutionError.from_cell_and_msg(cell, exec_reply_content)
nbclient.exceptions.CellExecutionError: An error occurred while executing the following cell:
------------------
data.paramFidelity()
------------------


[0;31m---------------------------------------------------------------------------[0m
[0;31mTypeError[0m                                 Traceback (most recent call last)
Cell [0;32mIn[42], line 1[0m
[0;32m----> 1[0m [43mdata[49m[38;5;241;43m.[39;49m[43mparamFidelity[49m[43m([49m[43m)[49m

File [0;32m~/github/PEMtk/pemtk/fit/_analysis.py:507[0m, in [0;36mparamFidelity[0;34m(self, key, dataDict, refDict, phaseCorr, phaseCorrParams)[0m
[1;32m    504[0m     phaseCorrArgs[38;5;241m.[39mupdate(phaseCorrParams)
[1;32m    506[0m     [38;5;66;03m# Run phaseCorrection()[39;00m
[0;32m--> 507[0m     [38;5;28;43mself[39;49m[38;5;241;43m.[39;49m[43mphaseCorrection[49m[43m([49m[38;5;241;43m*[39;49m[38;5;241;43m*[39;49m[43mphaseCorrArgs[49m[43m)[49m
[1;32m    508[0m     dfRef [38;5;241m=[39m [38;5;28mself[39m[38;5;241m.[39mdata[[38;5;124m'[39m[38;5;124mfits[39m[38;5;124m'[39m][[38;5;124m'[39m[38;5;124mdfRefPC[39m[38;5;124m'[39m]
[1;32m    510[0m [38;5;66;03m#*** Differences[39;00m
[1;32m    511[0m 
[1;32m    512[0m [38;5;66;03m# Set dataframe - actully, better to use class in this case...[39;00m

[0;31mTypeError[0m: phaseCorrection() got multiple values for argument 'self'

